<?xml version="1.0" encoding="UTF-8"?>
<robot name="Robot">
    <link name="iiwa_link_0">
        <inertial>
            <origin rpy="0.00000000 0.00000000 0.00000000" xyz="-0.10000000  0.00000000  0.07000000"/>
            <mass value="5.00000000"/>
            <inertia ixx="0.05000000" ixy="0.00000000" ixz="0.00000000" iyy="0.06000000" iyz="0.00000000" izz="0.03000000"/>
        </inertial>
        <visual>
            <origin rpy="0.00000000 0.00000000 0.00000000" xyz="0.00000000 0.00000000 0.00000000"/>
            <geometry>
                <mesh filename="meshes\visual\link_0.stl" scale="1.00000000 1.00000000 1.00000000"/>
            </geometry>
            <material name="">
                <color rgba="0.40000000 0.40000000 0.40000000 1.00000000"/>
            </material>
        </visual>
        <collision>
            <origin rpy="0.00000000 0.00000000 0.00000000" xyz="0.00000000 0.00000000 0.00000000"/>
            <geometry>
                <mesh filename="meshes\collision\link_0.stl" scale="1.00000000 1.00000000 1.00000000"/>
            </geometry>
        </collision>
    </link>
    <link name="iiwa_link_1">
        <inertial>
            <origin rpy="0.00000000 0.00000000 0.00000000" xyz="0.00000000 -0.03000000  0.12000000"/>
            <mass value="3.45250000"/>
            <inertia ixx="0.02183000" ixy="0.00000000" ixz="0.00000000" iyy="0.00770300" iyz="-0.00388700" izz="0.02083000"/>
        </inertial>
        <visual>
            <origin rpy="0.00000000 0.00000000 0.00000000" xyz="0.00000000 0.00000000 0.00750000"/>
            <geometry>
                <mesh filename="meshes\visual\link_1.stl" scale="1.00000000 1.00000000 1.00000000"/>
            </geometry>
            <material name="">
                <color rgba="1.00000000 0.42352941 0.03921569 1.00000000"/>
            </material>
        </visual>
        <collision>
            <origin rpy="0.00000000 0.00000000 0.00000000" xyz="0.00000000 0.00000000 0.00750000"/>
            <geometry>
                <mesh filename="meshes\collision\link_1.stl" scale="1.00000000 1.00000000 1.00000000"/>
            </geometry>
        </collision>
    </link>
    <link name="iiwa_link_2">
        <inertial>
            <origin rpy="0.00000000 0.00000000 0.00000000" xyz="0.00030000 0.05900000 0.04200000"/>
            <mass value="3.48210000"/>
            <inertia ixx="0.02076000" ixy="0.00000000" ixz="-0.00362600" iyy="0.02179000" iyz="0.00000000" izz="0.00779000"/>
        </inertial>
        <visual>
            <origin rpy="0.00000000 0.00000000 0.00000000" xyz="0.00000000 0.00000000 0.00000000"/>
            <geometry>
                <mesh filename="meshes\visual\link_2.stl" scale="1.00000000 1.00000000 1.00000000"/>
            </geometry>
            <material name="">
                <color rgba="1.00000000 0.42352941 0.03921569 1.00000000"/>
            </material>
        </visual>
        <collision>
            <origin rpy="0.00000000 0.00000000 0.00000000" xyz="0.00000000 0.00000000 0.00000000"/>
            <geometry>
                <mesh filename="meshes\collision\link_2.stl" scale="1.00000000 1.00000000 1.00000000"/>
            </geometry>
        </collision>
    </link>
    <link name="iiwa_link_3">
        <inertial>
            <origin rpy="0.00000000 0.00000000 0.00000000" xyz="0.00000000 0.03000000 0.13000000"/>
            <mass value="4.05623000"/>
            <inertia ixx="0.03204000" ixy="0.00000000" ixz="0.00000000" iyy="0.00972000" iyz="0.00622700" izz="0.03042000"/>
        </inertial>
        <visual>
            <origin rpy="0.00000000 0.00000000 0.00000000" xyz="0.00000000  0.00000000 -0.02600000"/>
            <geometry>
                <mesh filename="meshes\visual\link_3.stl" scale="1.00000000 1.00000000 1.00000000"/>
            </geometry>
            <material name="">
                <color rgba="1.00000000 0.42352941 0.03921569 1.00000000"/>
            </material>
        </visual>
        <collision>
            <origin rpy="0.00000000 0.00000000 0.00000000" xyz="0.00000000  0.00000000 -0.02600000"/>
            <geometry>
                <mesh filename="meshes\collision\link_3.stl" scale="1.00000000 1.00000000 1.00000000"/>
            </geometry>
        </collision>
    </link>
    <link name="iiwa_link_4">
        <inertial>
            <origin rpy="0.00000000 0.00000000 0.00000000" xyz="0.00000000 0.06700000 0.03400000"/>
            <mass value="3.48220000"/>
            <inertia ixx="0.02178000" ixy="0.00000000" ixz="0.00000000" iyy="0.02075000" iyz="-0.00362500" izz="0.00778500"/>
        </inertial>
        <visual>
            <origin rpy="0.00000000 0.00000000 0.00000000" xyz="0.00000000 0.00000000 0.00000000"/>
            <geometry>
                <mesh filename="meshes\visual\link_4.stl" scale="1.00000000 1.00000000 1.00000000"/>
            </geometry>
            <material name="">
                <color rgba="1.00000000 0.42352941 0.03921569 1.00000000"/>
            </material>
        </visual>
        <collision>
            <origin rpy="0.00000000 0.00000000 0.00000000" xyz="0.00000000 0.00000000 0.00000000"/>
            <geometry>
                <mesh filename="meshes\collision\link_4.stl" scale="1.00000000 1.00000000 1.00000000"/>
            </geometry>
        </collision>
    </link>
    <link name="iiwa_link_5">
        <inertial>
            <origin rpy="0.00000000 0.00000000 0.00000000" xyz="0.00010000 0.02100000 0.07600000"/>
            <mass value="2.16330000"/>
            <inertia ixx="0.01287000" ixy="0.00000000" ixz="0.00000000" iyy="0.00570800" iyz="-0.00394600" izz="0.01112000"/>
        </inertial>
        <visual>
            <origin rpy="0.00000000 0.00000000 0.00000000" xyz="0.00000000  0.00000000 -0.02600000"/>
            <geometry>
                <mesh filename="meshes\visual\link_5.stl" scale="1.00000000 1.00000000 1.00000000"/>
            </geometry>
            <material name="">
                <color rgba="1.00000000 0.42352941 0.03921569 1.00000000"/>
            </material>
        </visual>
        <collision>
            <origin rpy="0.00000000 0.00000000 0.00000000" xyz="0.00000000  0.00000000 -0.02600000"/>
            <geometry>
                <mesh filename="meshes\collision\link_5.stl" scale="1.00000000 1.00000000 1.00000000"/>
            </geometry>
        </collision>
    </link>
    <link name="iiwa_link_6">
        <inertial>
            <origin rpy="0.00000000 0.00000000 0.00000000" xyz="0.00000000 0.00060000 0.00040000"/>
            <mass value="2.34660000"/>
            <inertia ixx="0.00650900" ixy="0.00000000" ixz="0.00000000" iyy="0.00625900" iyz="0.00031891" izz="0.00452700"/>
        </inertial>
        <visual>
            <origin rpy="0.00000000 0.00000000 0.00000000" xyz="0.00000000 0.00000000 0.00000000"/>
            <geometry>
                <mesh filename="meshes\visual\link_6.stl" scale="1.00000000 1.00000000 1.00000000"/>
            </geometry>
            <material name="">
                <color rgba="1.00000000 0.42352941 0.03921569 1.00000000"/>
            </material>
        </visual>
        <collision>
            <origin rpy="0.00000000 0.00000000 0.00000000" xyz="0.00000000 0.00000000 0.00000000"/>
            <geometry>
                <mesh filename="meshes\collision\link_6.stl" scale="1.00000000 1.00000000 1.00000000"/>
            </geometry>
        </collision>
    </link>
    <link name="iiwa_link_7">
        <inertial>
            <origin rpy="0.00000000 0.00000000 0.00000000" xyz="0.00000000 0.00000000 0.02000000"/>
            <mass value="3.12900000"/>
            <inertia ixx="0.01464000" ixy="0.00059120" ixz="0.00000000" iyy="0.01465000" iyz="0.00000000" izz="0.00287200"/>
        </inertial>
        <visual>
            <origin rpy="0.00000000 0.00000000 0.00000000" xyz="0.00000000  0.00000000 -0.00050000"/>
            <geometry>
                <mesh filename="meshes\visual\link_7.stl" scale="1.00000000 1.00000000 1.00000000"/>
            </geometry>
            <material name="">
                <color rgba="0.40000000 0.40000000 0.40000000 1.00000000"/>
            </material>
        </visual>
        <collision>
            <origin rpy="0.00000000 0.00000000 0.00000000" xyz="0.00000000  0.00000000 -0.00050000"/>
            <geometry>
                <mesh filename="meshes\collision\link_7.stl" scale="1.00000000 1.00000000 1.00000000"/>
            </geometry>
        </collision>
    </link>
    <link name="iiwa_link_ee">
        <inertial>
            <origin rpy="0.00000000 0.00000000 0.00000000" xyz="0.00000000 0.00000000 0.00000000"/>
            <mass value="0.00000000"/>
            <inertia ixx="0.00000000" ixy="0.00000000" ixz="0.00000000" iyy="0.00000000" iyz="0.00000000" izz="0.00000000"/>
        </inertial>
    </link>
    <link name="iiwa_link_ee_kuka">
        <inertial>
            <origin rpy="0.00000000 0.00000000 0.00000000" xyz="0.00000000 0.00000000 0.00000000"/>
            <mass value="0.00000000"/>
            <inertia ixx="0.00000000" ixy="0.00000000" ixz="0.00000000" iyy="0.00000000" iyz="0.00000000" izz="0.00000000"/>
        </inertial>
    </link>
    <link name="world">
        <inertial>
            <mass value="0"/>
            <inertia ixx="0" ixy="0" ixz="0" iyy="0" iyz="0" izz="0"/>
        </inertial>
    </link>
    <joint name="iiwa_joint_1" type="revolute">
        <parent link="iiwa_link_0"/>
        <child link="iiwa_link_1"/>
        <origin rpy="0.00000000 0.00000000 0.00000000" xyz="0.00000000 0.00000000 0.15000000"/>
        <axis xyz="0.00000000 0.00000000 1.00000000"/>
        <limit lower="-2.96705973" upper="2.96705973" effort="0" velocity="0"/>
    </joint>
    <joint name="iiwa_joint_2" type="revolute">
        <parent link="iiwa_link_1"/>
        <child link="iiwa_link_2"/>
        <origin rpy="1.57079633  0.00000000 -3.14159265" xyz="0.00000000 0.00000000 0.19000000"/>
        <axis xyz="0.00000000 0.00000000 1.00000000"/>
        <limit lower="-2.09439510" upper="2.09439510" effort="0" velocity="0"/>
    </joint>
    <joint name="iiwa_joint_3" type="revolute">
        <parent link="iiwa_link_2"/>
        <child link="iiwa_link_3"/>
        <origin rpy="1.57079633  0.00000000 -3.14159265" xyz="0.00000000 0.21000000 0.00000000"/>
        <axis xyz="0.00000000 0.00000000 1.00000000"/>
        <limit lower="-2.96705973" upper="2.96705973" effort="0" velocity="0"/>
    </joint>
    <joint name="iiwa_joint_4" type="revolute">
        <parent link="iiwa_link_3"/>
        <child link="iiwa_link_4"/>
        <origin rpy="1.57079633 0.00000000 0.00000000" xyz="0.00000000 0.00000000 0.19000000"/>
        <axis xyz="0.00000000 0.00000000 1.00000000"/>
        <limit lower="-2.09439510" upper="2.09439510" effort="0" velocity="0"/>
    </joint>
    <joint name="iiwa_joint_5" type="revolute">
        <parent link="iiwa_link_4"/>
        <child link="iiwa_link_5"/>
        <origin rpy="1.57079633 -0.00000000 -3.14159265" xyz="0.00000000 0.21000000 0.00000000"/>
        <axis xyz="0.00000000 0.00000000 1.00000000"/>
        <limit lower="-2.96705973" upper="2.96705973" effort="0" velocity="0"/>
    </joint>
    <joint name="iiwa_joint_6" type="revolute">
        <parent link="iiwa_link_5"/>
        <child link="iiwa_link_6"/>
        <origin rpy="1.57079633 0.00000000 0.00000000" xyz="0.00000000 0.06070000 0.19000000"/>
        <axis xyz="0.00000000 0.00000000 1.00000000"/>
        <limit lower="-2.09439510" upper="2.09439510" effort="0" velocity="0"/>
    </joint>
    <joint name="iiwa_joint_7" type="revolute">
        <parent link="iiwa_link_6"/>
        <child link="iiwa_link_7"/>
        <origin rpy="1.57079633 -0.00000000 -3.14159265" xyz="0.00000000 0.08100000 0.06070000"/>
        <axis xyz="0.00000000 0.00000000 1.00000000"/>
        <limit lower="-3.05432619" upper="3.05432619" effort="0" velocity="0"/>
    </joint>
    <joint name="iiwa_joint_ee" type="fixed">
        <parent link="iiwa_link_7"/>
        <child link="iiwa_link_ee"/>
        <origin rpy="0.00000000 -1.57079633  0.00000000" xyz="0.00000000 0.00000000 0.04500000"/>
        <axis xyz="100"/>
    </joint>
    <joint name="iiwa_joint_ee_kuka" type="fixed">
        <parent link="iiwa_link_7"/>
        <child link="iiwa_link_ee_kuka"/>
        <origin rpy="0.00000000 -0.00000000  0.00000000" xyz="0.00000000 0.00000000 0.04500000"/>
        <axis xyz="100"/>
    </joint>
    <joint name="world_iiwa_joint" type="fixed">
        <parent link="world"/>
        <child link="iiwa_link_0"/>
        <origin rpy="0.00000000 0.00000000 0.00000000" xyz="0.00000000 0.00000000 0.00000000"/>
        <axis xyz="100"/>
    </joint>
</robot>
