<?xml version='1.0' encoding='UTF-8'?>
<robot name="GEN3_URDF_V12">
  <link name="world">
    <inertial>
      <origin xyz="0.0 0.0 0.0" rpy="0.0 -0.0 0.0"/>
      <mass value="1.0"/>
      <inertia ixx="1.0" ixy="0.0" ixz="0.0" iyy="1.0" iyz="0.0" izz="1.0"/>
    </inertial>
  </link>
  <link name="base_link">
    <inertial>
      <origin xyz="-0.000648 -0.000166 0.084487" rpy="0.0 0.0 0.0"/>
      <mass value="1.697"/>
      <inertia ixx="0.004622" ixy="9e-06" ixz="6e-05" iyy="0.004495" iyz="9e-06" izz="0.002079"/>
    </inertial>
    <visual>
      <geometry>
        <mesh filename="/mnt/c/Users/Nick/Documents/Github/ros_kortex/kortex_description/arms/gen3/7dof/meshes/base_link.STL"/>
      </geometry>
      <material name=""/>
      <origin xyz="0.0 0.0 0.0" rpy="0.0 0.0 0.0"/>
    </visual>
    <collision>
      <geometry>
        <mesh filename="/mnt/c/Users/Nick/Documents/Github/ros_kortex/kortex_description/arms/gen3/7dof/meshes/base_link.STL"/>
      </geometry>
      <origin xyz="0.0 0.0 0.0" rpy="0.0 0.0 0.0"/>
    </collision>
  </link>
  <link name="Shoulder_Link">
    <inertial>
      <origin xyz="-2.3e-05 -0.010364 -0.07336" rpy="0.0 0.0 0.0"/>
      <mass value="2.5"/>
      <inertia ixx="0.1" ixy="0.2" ixz="0.3" iyy="0.5" iyz="0.1" izz="0.3"/>
    </inertial>
    <visual>
      <geometry>
        <mesh filename="/mnt/c/Users/Nick/Documents/Github/ros_kortex/kortex_description/arms/gen3/7dof/meshes/shoulder_link.STL"/>
      </geometry>
      <material name=""/>
      <origin xyz="0.0 0.0 0.0" rpy="0.0 0.0 0.0"/>
    </visual>
    <collision>
      <geometry>
        <mesh filename="/mnt/c/Users/Nick/Documents/Github/ros_kortex/kortex_description/arms/gen3/7dof/meshes/shoulder_link.STL"/>
      </geometry>
      <origin xyz="0.0 0.0 0.0" rpy="0.0 0.0 0.0"/>
    </collision>
  </link>
  <link name="HalfArm1_Link">
    <inertial>
      <origin xyz="-4.4e-05 -0.09958 -0.013278" rpy="0.0 0.0 0.0"/>
      <mass value="2.5"/>
      <inertia ixx="0.1" ixy="0.2" ixz="0.3" iyy="0.5" iyz="0.1" izz="0.3"/>
    </inertial>
    <visual>
      <geometry>
        <mesh filename="/mnt/c/Users/Nick/Documents/Github/ros_kortex/kortex_description/arms/gen3/7dof/meshes/half_arm_1_link.STL"/>
      </geometry>
      <material name=""/>
      <origin xyz="0.0 0.0 0.0" rpy="0.0 0.0 0.0"/>
    </visual>
    <collision>
      <geometry>
        <mesh filename="/mnt/c/Users/Nick/Documents/Github/ros_kortex/kortex_description/arms/gen3/7dof/meshes/half_arm_1_link.STL"/>
      </geometry>
      <origin xyz="0.0 0.0 0.0" rpy="0.0 0.0 0.0"/>
    </collision>
  </link>
  <link name="HalfArm2_Link">
    <inertial>
      <origin xyz="-4.4e-05 -0.006641 -0.117892" rpy="0.0 0.0 0.0"/>
      <mass value="2.5"/>
      <inertia ixx="0.1" ixy="0.2" ixz="0.3" iyy="0.5" iyz="0.1" izz="0.3"/>
    </inertial>
    <visual>
      <geometry>
        <mesh filename="/mnt/c/Users/Nick/Documents/Github/ros_kortex/kortex_description/arms/gen3/7dof/meshes/half_arm_2_link.STL"/>
      </geometry>
      <material name=""/>
      <origin xyz="0.0 0.0 0.0" rpy="0.0 0.0 0.0"/>
    </visual>
    <collision>
      <geometry>
        <mesh filename="/mnt/c/Users/Nick/Documents/Github/ros_kortex/kortex_description/arms/gen3/7dof/meshes/half_arm_2_link.STL"/>
      </geometry>
      <origin xyz="0.0 0.0 0.0" rpy="0.0 0.0 0.0"/>
    </collision>
  </link>
  <link name="ForeArm_Link">
    <inertial>
      <origin xyz="-1.8e-05 -0.075478 -0.015006" rpy="0.0 0.0 0.0"/>
      <mass value="2.5"/>
      <inertia ixx="0.1" ixy="0.2" ixz="0.3" iyy="0.5" iyz="0.1" izz="0.3"/>
    </inertial>
    <visual>
      <geometry>
        <mesh filename="/mnt/c/Users/Nick/Documents/Github/ros_kortex/kortex_description/arms/gen3/7dof/meshes/forearm_link.STL"/>
      </geometry>
      <material name=""/>
      <origin xyz="0.0 0.0 0.0" rpy="0.0 0.0 0.0"/>
    </visual>
    <collision>
      <geometry>
        <mesh filename="/mnt/c/Users/Nick/Documents/Github/ros_kortex/kortex_description/arms/gen3/7dof/meshes/forearm_link.STL"/>
      </geometry>
      <origin xyz="0.0 0.0 0.0" rpy="0.0 0.0 0.0"/>
    </collision>
  </link>
  <link name="SphericalWrist1_Link">
    <inertial>
      <origin xyz="1e-06 -0.009432 -0.063883" rpy="0.0 0.0 0.0"/>
      <mass value="2.5"/>
      <inertia ixx="0.1" ixy="0.2" ixz="0.3" iyy="0.5" iyz="0.1" izz="0.3"/>
    </inertial>
    <visual>
      <geometry>
        <mesh filename="/mnt/c/Users/Nick/Documents/Github/ros_kortex/kortex_description/arms/gen3/7dof/meshes/spherical_wrist_1_link.STL"/>
      </geometry>
      <material name=""/>
      <origin xyz="0.0 0.0 0.0" rpy="0.0 0.0 0.0"/>
    </visual>
    <collision>
      <geometry>
        <mesh filename="/mnt/c/Users/Nick/Documents/Github/ros_kortex/kortex_description/arms/gen3/7dof/meshes/spherical_wrist_1_link.STL"/>
      </geometry>
      <origin xyz="0.0 0.0 0.0" rpy="0.0 0.0 0.0"/>
    </collision>
  </link>
  <link name="SphericalWrist2_Link">
    <inertial>
      <origin xyz="1e-06 -0.045483 -0.00965" rpy="0.0 0.0 0.0"/>
      <mass value="2.5"/>
      <inertia ixx="0.1" ixy="0.2" ixz="0.3" iyy="0.5" iyz="0.1" izz="0.3"/>
    </inertial>
    <visual>
      <geometry>
        <mesh filename="/mnt/c/Users/Nick/Documents/Github/ros_kortex/kortex_description/arms/gen3/7dof/meshes/spherical_wrist_2_link.STL"/>
      </geometry>
      <material name=""/>
      <origin xyz="0.0 0.0 0.0" rpy="0.0 0.0 0.0"/>
    </visual>
    <collision>
      <geometry>
        <mesh filename="/mnt/c/Users/Nick/Documents/Github/ros_kortex/kortex_description/arms/gen3/7dof/meshes/spherical_wrist_2_link.STL"/>
      </geometry>
      <origin xyz="0.0 0.0 0.0" rpy="0.0 0.0 0.0"/>
    </collision>
  </link>
  <link name="Bracelet_Link">
    <inertial>
      <origin xyz="-0.000281 -0.011402 -0.029798" rpy="0.0 0.0 0.0"/>
      <mass value="2.5"/>
      <inertia ixx="0.1" ixy="0.2" ixz="0.3" iyy="0.5" iyz="0.1" izz="0.3"/>
    </inertial>
    <visual>
      <geometry>
        <mesh filename="/mnt/c/Users/Nick/Documents/Github/ros_kortex/kortex_description/arms/gen3/7dof/meshes/bracelet_no_vision_link.STL"/>
      </geometry>
      <material name=""/>
      <origin xyz="0.0 0.0 0.0" rpy="0.0 0.0 0.0"/>
    </visual>
    <collision>
      <geometry>
        <mesh filename="/mnt/c/Users/Nick/Documents/Github/ros_kortex/kortex_description/arms/gen3/7dof/meshes/bracelet_no_vision_link.STL"/>
      </geometry>
      <origin xyz="0.0 0.0 0.0" rpy="0.0 0.0 0.0"/>
    </collision>
  </link>
  <link name="EndEffector_Link">
    <inertial>
      <origin xyz="0.0 0.0 0.0" rpy="0.0 -0.0 0.0"/>
      <mass value="1.0"/>
      <inertia ixx="1.0" ixy="0.0" ixz="0.0" iyy="1.0" iyz="0.0" izz="1.0"/>
    </inertial>
  </link>
  <joint name="base_link_joint" type="floating">
    <parent link="world"/>
    <child link="base_link"/>
    <axis xyz="1. 0. 0."/>
    <origin xyz="0.0 0.0 0.0" rpy="0.0 0.0 0.0"/>
  </joint>
  <joint name="Actuator1" type="revolute">
    <limit effort="39.0" velocity="0.8727"/>
    <parent link="base_link"/>
    <child link="Shoulder_Link"/>
    <axis xyz="0. 0. 1."/>
    <origin xyz="0.0 0.0 0.15643" rpy="-3.1415853071795867 2.7629e-18 -4.9305e-36"/>
  </joint>
  <joint name="Actuator2" type="revolute">
    <limit effort="39.0" velocity="0.8727" lower="-2.41" upper="2.41"/>
    <parent link="Shoulder_Link"/>
    <child link="HalfArm1_Link"/>
    <axis xyz="0. 0. 1."/>
    <origin xyz="0.0 0.005375 -0.12838" rpy="1.5708 2.1343e-17 -1.1102e-16"/>
  </joint>
  <joint name="Actuator3" type="revolute">
    <limit effort="39.0" velocity="0.8727"/>
    <parent link="HalfArm1_Link"/>
    <child link="HalfArm2_Link"/>
    <axis xyz="0. 0. 1."/>
    <origin xyz="0.0 -0.21038 -0.006375" rpy="-1.5708 1.2326e-32 -2.9122e-16"/>
  </joint>
  <joint name="Actuator4" type="revolute">
    <limit effort="39.0" velocity="0.8727" lower="-2.66" upper="2.66"/>
    <parent link="HalfArm2_Link"/>
    <child link="ForeArm_Link"/>
    <axis xyz="0. 0. 1."/>
    <origin xyz="0.0 0.006375 -0.21038" rpy="1.5708 -6.6954e-17 -1.6653e-16"/>
  </joint>
  <joint name="Actuator5" type="revolute">
    <limit effort="9.0" velocity="0.8727"/>
    <parent link="ForeArm_Link"/>
    <child link="SphericalWrist1_Link"/>
    <axis xyz="0. 0. 1."/>
    <origin xyz="0.0 -0.20843 -0.006375" rpy="-1.5708 2.2204e-16 -6.373e-17"/>
  </joint>
  <joint name="Actuator6" type="revolute">
    <limit effort="9.0" velocity="0.8727" lower="-2.23" upper="2.23"/>
    <parent link="SphericalWrist1_Link"/>
    <child link="SphericalWrist2_Link"/>
    <axis xyz="0. 0. 1."/>
    <origin xyz="0.0 0.00017505 -0.10593" rpy="1.5708 9.2076e-28 -8.2157e-15"/>
  </joint>
  <joint name="Actuator7" type="revolute">
    <limit effort="9.0" velocity="0.8727"/>
    <parent link="SphericalWrist2_Link"/>
    <child link="Bracelet_Link"/>
    <axis xyz="0. 0. 1."/>
    <origin xyz="0.0 -0.10593 -0.00017505" rpy="-1.5708 -5.5511e-17 9.6396e-17"/>
  </joint>
  <joint name="EndEffector" type="fixed">
    <parent link="Bracelet_Link"/>
    <child link="EndEffector_Link"/>
    <axis xyz="nan nan nan"/>
    <origin xyz="0.0 0.0 -0.0615250000000001" rpy="3.14159265358979 1.09937075168372e-32 0.0"/>
  </joint>
  <material name="">
    <color rgba="0.75294 0.75294 0.75294 1.     "/>
  </material>
</robot>
